Traceback (most recent call last):
  File "/home/flashshipper/.virtualenvs/flashshipper-virtualenv/lib/python3.7/site-packages/urllib3/connection.py", line 160, in _new_conn
    (self._dns_host, self.port), self.timeout, **extra_kw)
  File "/home/flashshipper/.virtualenvs/flashshipper-virtualenv/lib/python3.7/site-packages/urllib3/util/connection.py", line 80, in create_connection
    raise err
  File "/home/flashshipper/.virtualenvs/flashshipper-virtualenv/lib/python3.7/site-packages/urllib3/util/connection.py", line 70, in create_connection
    sock.connect(sa)
ConnectionRefusedError: [Errno 111] Connection refused

During handling of the above exception, another exception occurred:

Traceback (most recent call last):
  File "/home/flashshipper/.virtualenvs/flashshipper-virtualenv/lib/python3.7/site-packages/urllib3/connectionpool.py", line 603, in urlopen
    chunked=chunked)
  File "/home/flashshipper/.virtualenvs/flashshipper-virtualenv/lib/python3.7/site-packages/urllib3/connectionpool.py", line 344, in _make_request
    self._validate_conn(conn)
  File "/home/flashshipper/.virtualenvs/flashshipper-virtualenv/lib/python3.7/site-packages/urllib3/connectionpool.py", line 843, in _validate_conn
    conn.connect()
  File "/home/flashshipper/.virtualenvs/flashshipper-virtualenv/lib/python3.7/site-packages/urllib3/connection.py", line 316, in connect
    conn = self._new_conn()
  File "/home/flashshipper/.virtualenvs/flashshipper-virtualenv/lib/python3.7/site-packages/urllib3/connection.py", line 169, in _new_conn
    self, "Failed to establish a new connection: %s" % e)
urllib3.exceptions.NewConnectionError: <urllib3.connection.VerifiedHTTPSConnection object at 0x7ffa525cef28>: Failed to establish a new connection: [Errno 111] Connection refused

During handling of the above exception, another exception occurred:

Traceback (most recent call last):
  File "/home/flashshipper/.virtualenvs/flashshipper-virtualenv/lib/python3.7/site-packages/requests/adapters.py", line 449, in send
    timeout=timeout
  File "/home/flashshipper/.virtualenvs/flashshipper-virtualenv/lib/python3.7/site-packages/urllib3/connectionpool.py", line 641, in urlopen
    _stacktrace=sys.exc_info()[2])
  File "/home/flashshipper/.virtualenvs/flashshipper-virtualenv/lib/python3.7/site-packages/urllib3/util/retry.py", line 399, in increment
    raise MaxRetryError(_pool, url, error or ResponseError(cause))
urllib3.exceptions.MaxRetryError: HTTPSConnectionPool(host='api.twilio.com', port=443): Max retries exceeded with url: /2010-04-01/Accounts/AC9f05e812b5954718ee0e25f764ec5c6d/Messages.json (Caused by NewConnectionError('<urllib3.connection.VerifiedHTTPSConnection object at 0x7ffa525cef28>: Failed to establish a new connection: [Errno 111] Connection refused'))

During handling of the above exception, another exception occurred:

Traceback (most recent call last):
  File "send_sms.py", line 18, in <module>
    to          = send_to_phone_number
  File "/home/flashshipper/.virtualenvs/flashshipper-virtualenv/lib/python3.7/site-packages/twilio/rest/api/v2010/account/message/__init__.py", line 87, in create
    data=data,
  File "/home/flashshipper/.virtualenvs/flashshipper-virtualenv/lib/python3.7/site-packages/twilio/base/version.py", line 205, in create
    allow_redirects=allow_redirects,
  File "/home/flashshipper/.virtualenvs/flashshipper-virtualenv/lib/python3.7/site-packages/twilio/base/version.py", line 47, in request
    allow_redirects=allow_redirects
  File "/home/flashshipper/.virtualenvs/flashshipper-virtualenv/lib/python3.7/site-packages/twilio/base/domain.py", line 46, in request
    allow_redirects=allow_redirects
  File "/home/flashshipper/.virtualenvs/flashshipper-virtualenv/lib/python3.7/site-packages/twilio/rest/__init__.py", line 130, in request
    allow_redirects=allow_redirects
  File "/home/flashshipper/.virtualenvs/flashshipper-virtualenv/lib/python3.7/site-packages/twilio/http/http_client.py", line 68, in request
    timeout=timeout,
  File "/home/flashshipper/.virtualenvs/flashshipper-virtualenv/lib/python3.7/site-packages/requests/sessions.py", line 646, in send
    r = adapter.send(request, **kwargs)
  File "/home/flashshipper/.virtualenvs/flashshipper-virtualenv/lib/python3.7/site-packages/requests/adapters.py", line 516, in send
    raise ConnectionError(e, request=request)
requests.exceptions.ConnectionError: HTTPSConnectionPool(host='api.twilio.com', port=443): Max retries exceeded with url: /2010-04-01/Accounts/AC9f05e812b5954718ee0e25f764ec5c6d/Messages.json (Caused by NewConnectionError('<urllib3.connection.VerifiedHTTPSConnection object at 0x7ffa525cef28>: Failed to establis
h a new connection: [Errno 111] Connection refused'))


---------------------------------------
https://forums.autodesk.com/t5/bim-360-api-forum/why-i-get-complained-about-quot-max-retries-exceeded-with-url/td-p/7426570

I found the reason, it is because of the limit of inflow data-size in our proxy.

Instead of one single API call for returning all EQUIPMENT's attachment data of one project,

i need to break it down as a loop with parameters offset & limit set as 30. 

The reason 'Max retries exceeded' is definitely misleading.